#+TITLE: 错误处理
#+HTML_HEAD: <link rel="stylesheet" type="text/css" href="css/main.css" />
#+HTML_LINK_UP: basic.html   
#+HTML_LINK_HOME: go-patterns.html
#+OPTIONS: num:nil timestamp:nil

#+begin_example
  错误处理一直以一是编程必需要面对的问题，错误处理如果做的好的话，代码的稳定性会很好

  不同的语言有不同的出现处理的方式，Go语言也一样
#+end_example

在本篇文章中讨论一下Go语言的出错出处，尤其是那令人抓狂的 if err != nil 

#+begin_example
  在正式讨论Go代码里满屏的 if err != nil 怎么办这个事之前，想先说一说编程中的错误处理

  这样可以在更高的层面理解编程中的错误处理
#+end_example
* C 
  首先，处理错误最直接的方式是通过错误码，这也是传统的方式，在过程式语言中通常都是用这样的方式处理错误的。比如 C 语言，基本上来说：
  + 通过 _函数的返回值标识_ 是否有错
  + 通过 *全局的 errno 变量* 并配合一个 _errstr 的数组_ 来告诉为什么出错 

  #+begin_example
    为什么是这样的设计？道理很简单，除了可以共用一些错误，更重要的是这其实是一种妥协

    比如：read(), write(), open() 这些函数的返回值其实是返回有业务逻辑的值。也就是说，这些函数的返回值有两种语义，一种是成功的值，比如 open() 返回的文件句柄指针 FILE* ，或是错误 NULL

    这样会导致调用者并不知道是什么原因出错了，需要去检查 errno 来获得出错的原因，从而可以正确地处理错误
  #+end_example

  一般而言，这样的错误处理方式在大多数情况下是没什么问题的。但是也有例外的情况，来看一下下面这个 C 语言的函数：

  #+begin_src c 
  int atoi(const char *str)
  #+end_src

  这个函数是把一个字符串转成整型

  #+begin_example
    但是问题来了，如果一个要传的字符串是非法的（不是数字的格式），如 “ABC” 或者整型溢出了，那么这个函数应该返回什么呢？

    出错返回，返回什么数都不合理，因为这会和正常的结果混淆在一起

    比如，返回 0，那么会和正常的对 “0” 字符的返回值完全混淆在一起。这样就无法判断出错的情况

  #+end_example
  可能会说，是不是要检查一下 errno，按道理说应该是要去检查的，但是，在 C99 的规格说明书中可以看到这样的描述：

  #+begin_example
    7.20.1 The functions atof, atoi, atol, and atoll need not affect the value of the integer expression errno on an error. If the value of the result cannot be represented, the behavior is undefined.
  #+end_example

  像atoi(), atof(), atol() 或是 atoll() 这样的函数是不会设置 errno的，而且还说了，如果结果无法计算的话，行为是undefined。所以，后来 libc 又给出了一个新的函数strtol()，这个函数在出错的时会设置全局变量 errno ：

  #+begin_src c 
  long val = strtol(in_str, &endptr, 10);  //10的意思是10进制
  //如果无法转换
  if (endptr == str) {
	  fprintf(stderr, "No digits were found\n");
	  exit(EXIT_FAILURE);
  }

  //如果整型溢出了
  if (errno == ERANGE && (val == LONG_MAX || val == LONG_MIN)) {
	  fprintf(stderr, "ERROR: number out of range for LONG\n");
	  exit(EXIT_FAILURE);
  }

  //如果是其它错误
  if (errno != 0 && val == 0) {
	  perror("strtol");
	  exit(EXIT_FAILURE);
  }        
  #+end_src

  #+begin_example
    虽然，strtol() 函数解决了 atoi() 函数的问题，但是还是能感觉到不是很舒服和自然
  #+end_example

  因为，这种用 返回值 + errno 的错误检查方式会有一些问题:
  + 程序员一不小心就会忘记返回值的检查，从而造成代码的 Bug
  + 函数接口非常不纯洁，正常值和错误值混淆在一起，导致语义有问题。

  所以后来，有一些类库就开始区分这样的事情。比如，Windows 的系统调用开始使用 HRESULT 的返回来统一错误的返回值，这样可以明确函数调用时的返回值是成功还是错误
  #+begin_example
    但这样一来，函数的 input 和 output 只能通过函数的参数来完成，于是出现了所谓的 入参 和 出参这样的区别

    然而这又使得函数接入中参数的语义变得复杂，一些参数是入参，一些参数是出参，函数接口变得复杂了一些

    而且依然没有解决函数的成功或失败可以被人为忽略的问题
  #+end_example
* Java 
  Java语言使用 _try-catch-finally_ 通过使用异常的方式来处理错误，这比起C语言的错处理进了一大步，使用抛异常和抓异常的方式可以让代码有这样的一些好处：
  + 函数接口在 input（参数）和 output（返回值）以及错误处理的语义是比较清楚的
  + 正常逻辑的代码可以与错误处理和资源清理的代码分开，提高了代码的可读性
  + 异常不能被忽略（如果要忽略也需要 catch 住，这是显式忽略）
  + 在面向对象的语言中（如 Java），异常是个对象，可以实现多态式的 catch
  + 与状态返回码相比，异常捕捉有一个显著的好处是，函数可以嵌套调用，或是链式调用。比如：
  #+begin_src java 
  int x = add(a, div(b,c));

  Pizza p = PizzaBuilder().SetSize(sz).SetPrice(p);
  #+end_src
* Go 
  Go 语言的函数支持多返回值，所以，可以在返回接口把业务语义（业务返回值）和控制语义（出错返回值）区分开来。Go 语言的很多函数都会返回 _result, err_ 两个值，于是:
  + 参数上基本上就是入参，而返回接口把结果和错误分离，这样使得函数的接口语义清晰
  + Go 语言中的错误参数如果要忽略，需要显式地忽略，用 _ 这样的变量来忽略
  + 因为返回的 error 是个接口（其中只有一个方法 Error()，返回一个 string ），所以可以扩展自定义的错误处理 

  另外，如果一个函数返回了多个不同类型的 error，可以使用下面这样的方式：
  #+begin_src go 
  if err != nil {
    switch err.(type) {
      case *json.SyntaxError:
	...
      case *ZeroDivisionError:
	...
      case *NullPointerError:
	...
      default:
	...
    }
  }
  #+end_src

  #+begin_example
    Go语言的错误处理的的方式，本质上是返回值检查，但是也兼顾了异常的一些好处：对错误的扩展
  #+end_example

** 错误检查噩梦
   #+begin_example
   好了，说到 Go 语言的 if err !=nil 的代码了，这样的代码的确是能让人写到吐。那么有没有什么好的方式呢
   #+end_example
   先看如下的一个令人崩溃的代码：

   #+begin_src go 
  func parse(r io.Reader) (*Point, error) {
	  var p Point

	  if err := binary.Read(r, binary.BigEndian, &p.Longitude); err != nil {
		  return nil, err
	  }
	  if err := binary.Read(r, binary.BigEndian, &p.Latitude); err != nil {
		  return nil, err
	  }
	  if err := binary.Read(r, binary.BigEndian, &p.Distance); err != nil {
		  return nil, err
	  }
	  if err := binary.Read(r, binary.BigEndian, &p.ElevationGain); err != nil {
		  return nil, err
	  }
	  if err := binary.Read(r, binary.BigEndian, &p.ElevationLoss); err != nil {
		  return nil, err
	  }
  }
   #+end_src

   要解决这个事，可以用函数式编程的方式，如下代码示例：

   #+begin_src go 
  func parse(r io.Reader) (*Point, error) {
	  var p Point
	  var err error
	  read := func(data interface{}) {
		  if err != nil {
			  return
		  }
		  err = binary.Read(r, binary.BigEndian, data)
	  }

	  read(&p.Longitude)
	  read(&p.Latitude)
	  read(&p.Distance)
	  read(&p.ElevationGain)
	  read(&p.ElevationLoss)

	  if err != nil {
		  return &p, err
	  }
	  return &p, nil
  }
   #+end_src 

   通过使用 _闭包_ 的方式把相同的代码给抽出来重新定义一个函数，这样大量的  if err!=nil 处理的很干净了
   #+begin_example
   但是会带来一个问题，那就是有一个 err 变量和一个内部的函数，感觉不是很干净 
   #+end_example

   从Go 语言的 bufio.Scanner()中似乎可以学习到一些东西：

   #+begin_src go 
  scanner := bufio.NewScanner(input)

  for scanner.Scan() {
      token := scanner.Text()
      // process token
  }

  if err := scanner.Err(); err != nil {
      // process the error
  }
   #+end_src

   #+begin_example
     scanner在操作底层的I/O的时候，那个for-loop中没有任何的 if err !=nil 的情况，退出循环后有一个 scanner.Err() 的检查
   #+end_example

   这是使用了 _结构体_ 的方式。现在来模仿它，首先定义一个结构体和函数： 

   #+begin_src go 
  type Reader struct {
	  r   io.Reader
	  err error
  }

  func (r *Reader) read(data interface{}) {
	  if r.err == nil {
		  r.err = binary.Read(r.r, binary.BigEndian, data)
	  }
  }
   #+end_src

   然后代码就可以变成下面这样：

   #+begin_src go 
  func parse(input io.Reader) (*Point, error) {
	  var p Point
	  r := Reader{r: input}

	  r.read(&p.Longitude)
	  r.read(&p.Latitude)
	  r.read(&p.Distance)
	  r.read(&p.ElevationGain)
	  r.read(&p.ElevationLoss)

	  if r.err != nil {
		  return nil, r.err
	  }

	  return &p, nil
  }
   #+end_src

   有了上面这个技术，我们的 _流式接口_ ，也就很容易处理了。如下所示：

   #+begin_src go 
  package main

  import (
	  "bytes"
	  "encoding/binary"
	  "fmt"
  )

  // 长度不够，少一个Weight
  var b = []byte {0x48, 0x61, 0x6f, 0x20, 0x43, 0x68, 0x65, 0x6e, 0x00, 0x00, 0x2c} 
  var r = bytes.NewReader(b)

  type Person struct {
	  Name [10]byte
	  Age uint8
	  Weight uint8
	  err error
  }
  func (p *Person) read(data interface{}) {
	  if p.err == nil {
		  p.err = binary.Read(r, binary.BigEndian, data)
	  }
  }

  func (p *Person) ReadName() *Person {
	  p.read(&p.Name) 
	  return p
  }

  func (p *Person) ReadAge() *Person {
	  p.read(&p.Age) 
	  return p
  }

  func (p *Person) ReadWeight() *Person {
	  p.read(&p.Weight) 
	  return p
  }

  func (p *Person) Print() *Person {
	  if p.err == nil {
		  fmt.Printf("Name=%s, Age=%d, Weight=%d\n",p.Name, p.Age, p.Weight)
	  }
	  return p
  }

  func main() {   
	  p := Person{}
	  p.ReadName().ReadAge().ReadWeight().Print()
	  fmt.Println(p.err)  // EOF 错误
  }
   #+end_src 

   #+begin_example
     但是，其使用场景也就只能在对于同一个业务对象的不断操作下可以简化错误处理

     对于多个业务对象的话，还是得需要各种 if err != nil的方式
   #+end_example

** 包装错误
   #+begin_example
     最后，需要包装一下错误，而不是干巴巴地把err给返回到上层，而是把一些执行的上下文加入
   #+end_example

   通常来说，会使用 _fmt.Errorf()_ 来完成这个事，比如：

   #+begin_src go 
  if err != nil {
	  return fmt.Errorf("something failed: %v", err)
  }
   #+end_src

   另外，在Go语言的开发者中，更为普遍的做法是将 _错误_ *包装* 在 _另一个错误_ 中，同时 *保留* _原始内容_ ：

   #+begin_src go 
  type authorizationError struct {
	  operation string
	  err error   // original error
  }

  func (e *authorizationError) Error() string {
	  return fmt.Sprintf("authorization failed during %s: %v", e.operation, e.err)
  }
   #+end_src

   当然，更好的方式是通过一种标准的访问方法，这样，最好使用一个接口，比如 causer接口中实现 Cause() 方法来暴露原始错误，以供进一步检查：

   #+begin_src go 
  type causer interface {
	  Cause() error
  }

  func (e *authorizationError) Cause() error {
	  return e.err
  }
   #+end_src 

   这里有个好消息是，这样的代码不必再写了，有一个第三方的错误库 _github.com/pkg/errors_ 
   #+begin_example
   对于这个库，无论到哪都能看到他的存在，所以，这个基本上来说就是事实上的标准了
   #+end_example

   代码示例如下：
   #+begin_src go 
  import "github.com/pkg/errors"

  //错误包装
  if err != nil {
	  return errors.Wrap(err, "read failed")
  }

  // Cause接口
  switch err := errors.Cause(err).(type) {
  case *MyError:
	  // handle specifically
  default:
	  // unknown error
  }
   #+end_src

* 资源清理
  出错后是需要做资源清理的，不同的编程语言有不同的资源清理的编程模式：
  + C：使用的是 _goto fail;_ 的方式到一个集中的地方进行清理
  + C++：一般来说使用 _RAII_ 模式，通过面向对象的 *代理* 模式，把需要清理的资源交给一个 _代理类_ ，然后在 _析构函数_ 来解决
  + Java：可以在 _finally_ 语句块里进行清理
  + Go：使用 _defer_ 关键词进行清理 

  下面是一个Go语言的资源清理的示例：
  #+begin_src go 
  func Close(c io.Closer) {
	  err := c.Close()
	  if err != nil {
		  log.Fatal(err)
	  }
  }

  func main() {
	  r, err := Open("a")
	  if err != nil {
		  log.Fatalf("error opening 'a'\n")
	  }
	  defer Close(r) // 使用defer关键字在函数退出时关闭文件。

	  r, err = Open("b")
	  if err != nil {
		  log.Fatalf("error opening 'b'\n")
	  }
	  defer Close(r) // 使用defer关键字在函数退出时关闭文件。
  }
  #+end_src

[[file:function.org][Next：函数式配置]]

[[file:basic.org][Previous：基础概念]]

[[file:go-patterns.org][Home：目录]]
